Workbook

Sheet Cover
B2: CUVR
B3: 5-Year Financial Model
B4: VR-gamified rehabilitation · UAE / GCC · B2B2C
B5: Prepared April 2026 · v1.0 · Confidential
B7: Currency | C7: AED (United Arab Emirates Dirham) · USD reference at AED 3.67 / USD
B8: Period | C8: FY2026 – FY2030 (calendar year, FY2026 = first commercial year)
B9: Geography | C9: UAE (FY2026–27), KSA entry FY2028, broader GCC FY2029–30
B11: Workbook Structure
B13: Cover | C13: This sheet — model overview and navigation
B14: Assumptions | C14: All input drivers; ALL blue cells are user-editable
B15: Revenue | C15: Bottom-up build: site count × ARPU components
B16: COGS | C16: Hardware, hosting, content licensing, support
B17: OpEx | C17: Headcount + non-payroll operating expenses
B18: P&L | C18: Income statement, FY2026–FY2030
B19: CashFlow | C19: Operating + investing + financing cash flow
B20: Funding | C20: Capital plan: pre-seed, seed, Series A, B
B21: CapTable | C21: Ownership evolution + dilution
B22: Scenarios | C22: Base / Conservative / Aggressive sensitivity
B23: Summary | C23: 1-page executive summary
B25: Color Coding
B27: Blue text | C27: Hardcoded inputs / assumptions you can change
B28: Black text | C28: Formulas — do not edit manually
B29: Green text | C29: Links pulling from another sheet
B30: Yellow fill | C30: Key driver — pay close attention

Sheet Assumptions
B2: Assumptions
B3: All inputs in BLUE. Edit these to flex the model.
B5: Driver | C5: Unit | D5: FY2026 | E5: FY2027 | F5: FY2028 | G5: FY2029 | H5: FY2030 | I5: Notes
B7: 1. Site Counts (cumulative active sites at year-end)
B8: UAE — Independent physio clinics | C8: sites | D8: 4 | E8: 14 | F8: 32 | G8: 60 | H8: 95 | I8: Phase 1 pilots → broad rollout
B9: UAE — Mid/large hospital systems | C9: sites | D9: 1 | E9: 4 | F9: 12 | G9: 24 | H9: 38 | I9: Aster, Mediclinic, NMC, EHS
B10: UAE — Home-health agencies | C10: sites | D10: 0 | E10: 2 | F10: 8 | G10: 18 | H10: 30 | I10: Phase 2 onwards
B11: KSA — Hospitals & clinics | C11: sites | D11: 0 | E11: 0 | F11: 8 | G11: 28 | H11: 65 | I11: Post-SFDA registration
B12: Other GCC (KW, BH, QA, OM) | C12: sites | D12: 0 | E12: 0 | F12: 2 | G12: 10 | H12: 28 | I12: Post-MoHAP MDRC
B14: 2. ARPU — Setup / Hardware One-Time Fee (per new site)
B15: Setup fee — Independent clinic | C15: AED | D15: 18000 | E15: 19000 | F15: 20000 | G15: 21000 | H15: 22000 | I15: Hardware + onboarding
B16: Setup fee — Hospital system | C16: AED | D16: 45000 | E16: 47000 | F16: 50000 | G16: 52000 | H16: 55000 | I16: Multi-room deployment
B17: Setup fee — Home-health agency | C17: AED | D17: 12000 | E17: 13000 | F17: 13500 | G17: 14000 | H17: 14500 | I17: Lighter footprint
B18: Setup fee — KSA / GCC site (blended) | C18: AED | D18: 0 | E18: 0 | F18: 22000 | G18: 23000 | H18: 24000
B20: 3. ARPU — Recurring SaaS (per site, per month)
B21: Monthly SaaS — Clinic | C21: AED/mo | D21: 4500 | E21: 4700 | F21: 4900 | G21: 5100 | H21: 5300
B22: Monthly SaaS — Hospital | C22: AED/mo | D22: 9500 | E22: 9800 | F22: 10000 | G22: 10300 | H22: 10600
B23: Monthly SaaS — Home-health | C23: AED/mo | D23: 3000 | E23: 3100 | F23: 3200 | G23: 3300 | H23: 3400
B24: Monthly SaaS — KSA / GCC | C24: AED/mo | D24: 0 | E24: 0 | F24: 5000 | G24: 5200 | H24: 5400
B26: 4. Per-Session Revenue (variable usage)
B27: Sessions per site per month — Clinic | C27: # | D27: 180 | E27: 220 | F27: 260 | G27: 290 | H27: 320
B28: Sessions per site per month — Hospital | C28: # | D28: 320 | E28: 380 | F28: 440 | G28: 500 | H28: 560
B29: Sessions per site per month — Home-health | C29: # | D29: 80 | E29: 120 | F29: 180 | G29: 220 | H29: 260
B30: Sessions per site per month — KSA / GCC | C30: # | D30: 0 | E30: 0 | F30: 200 | G30: 260 | H30: 320
B31: Revenue per session (blended) | C31: AED | D31: 35 | E31: 38 | F31: 42 | G31: 48 | H31: 55 | I31: Mix of cash-pay and reimbursed
B33: 5. Site Activation Timing
B34: % of new sites active half-year (avg) | C34: % | D34: 0.5 | E34: 0.5 | F34: 0.6 | G34: 0.6 | H34: 0.65 | I34: Time-weighted ARR factor
B36: 6. COGS Drivers
B37: Hardware COGS per setup (avg) | C37: AED | D37: 9000 | E37: 8500 | F37: 8000 | G37: 7800 | H37: 7500 | I37: Quest Pro/3 + accessories
B38: Cloud + hosting per site per month | C38: AED/mo | D38: 180 | E38: 170 | F38: 160 | G38: 150 | H38: 140
B39: Content licensing per session | C39: AED | D39: 3 | E39: 3 | F39: 2.5 | G39: 2 | H39: 2
B40: Customer support per site per month | C40: AED/mo | D40: 220 | E40: 200 | F40: 180 | G40: 170 | H40: 160
B42: 7. Headcount (FTEs at year-end)
B43: Engineering + Product | C43: # | D43: 4 | E43: 8 | F43: 14 | G43: 22 | H43: 32
B44: Clinical + Reg Affairs | C44: # | D44: 2 | E44: 4 | F44: 6 | G44: 9 | H44: 13
B45: Sales + Customer Success | C45: # | D45: 2 | E45: 5 | F45: 12 | G45: 22 | H45: 38
B46: G&A (Finance, HR, Ops) | C46: # | D46: 1 | E46: 3 | F46: 5 | G46: 8 | H46: 12
B47: Avg fully-loaded cost per FTE | C47: AED/yr | D47: 320000 | E47: 340000 | F47: 360000 | G47: 380000 | H47: 400000 | I47: Includes EOSB, healthcare, etc.
B49: 8. Non-Payroll OpEx
B50: Marketing & demand gen | C50: AED | D50: 400000 | E50: 1500000 | F50: 4500000 | G50: 9000000 | H50: 16000000
...

Sheet Revenue
B2: Revenue Build
B3: Bottom-up: site count × (setup fee + 12 × monthly SaaS + 12 × sessions × per-session)
B5: Line Item | C5: Unit | D5: FY2026 | E5: FY2027 | F5: FY2028 | G5: FY2029 | H5: FY2030
B7: Site counts (cumulative, year-end)
B8: UAE clinics | C8: sites | D8: =Assumptions!D8 -> 4 | E8: =Assumptions!E8 -> 14 | F8: =Assumptions!F8 -> 32 | G8: =Assumptions!G8 -> 60 | H8: =Assumptions!H8 -> 95
B9: UAE hospitals | C9: sites | D9: =Assumptions!D9 -> 1 | E9: =Assumptions!E9 -> 4 | F9: =Assumptions!F9 -> 12 | G9: =Assumptions!G9 -> 24 | H9: =Assumptions!H9 -> 38
B10: UAE home-health | C10: sites | D10: =Assumptions!D10 -> 0 | E10: =Assumptions!E10 -> 2 | F10: =Assumptions!F10 -> 8 | G10: =Assumptions!G10 -> 18 | H10: =Assumptions!H10 -> 30
B11: KSA sites | C11: sites | D11: =Assumptions!D11 -> 0 | E11: =Assumptions!E11 -> 0 | F11: =Assumptions!F11 -> 8 | G11: =Assumptions!G11 -> 28 | H11: =Assumptions!H11 -> 65
B12: Other GCC sites | C12: sites | D12: =Assumptions!D12 -> 0 | E12: =Assumptions!E12 -> 0 | F12: =Assumptions!F12 -> 2 | G12: =Assumptions!G12 -> 10 | H12: =Assumptions!H12 -> 28
B13: Total sites (year-end) | C13: sites | D13: =SUM(D8:D12) -> 5 | E13: =SUM(E8:E12) -> 20 | F13: =SUM(F8:F12) -> 62 | G13: =SUM(G8:G12) -> 140 | H13: =SUM(H8:H12) -> 256
B15: Net new sites added during year
B16: UAE clinics (new) | C16: sites | D16: =Assumptions!D8 -> 4 | E16: =Assumptions!E8-Assumptions!D8 -> 10 | F16: =Assumptions!F8-Assumptions!E8 -> 18 | G16: =Assumptions!G8-Assumptions!F8 -> 28 | H16: =Assumptions!H8-Assumptions!G8 -> 35
B17: UAE hospitals (new) | C17: sites | D17: =Assumptions!D9 -> 1 | E17: =Assumptions!E9-Assumptions!D9 -> 3 | F17: =Assumptions!F9-Assumptions!E9 -> 8 | G17: =Assumptions!G9-Assumptions!F9 -> 12 | H17: =Assumptions!H9-Assumptions!G9 -> 14
B18: UAE home-health (new) | C18: sites | D18: =Assumptions!D10 -> 0 | E18: =Assumptions!E10-Assumptions!D10 -> 2 | F18: =Assumptions!F10-Assumptions!E10 -> 6 | G18: =Assumptions!G10-Assumptions!F10 -> 10 | H18: =Assumptions!H10-Assumptions!G10 -> 12
B19: KSA (new) | C19: sites | D19: =Assumptions!D11 -> 0 | E19: =Assumptions!E11-Assumptions!D11 -> 0 | F19: =Assumptions!F11-Assumptions!E11 -> 8 | G19: =Assumptions!G11-Assumptions!F11 -> 20 | H19: =Assumptions!H11-Assumptions!G11 -> 37
B20: Other GCC (new) | C20: sites | D20: =Assumptions!D12 -> 0 | E20: =Assumptions!E12-Assumptions!D12 -> 0 | F20: =Assumptions!F12-Assumptions!E12 -> 2 | G20: =Assumptions!G12-Assumptions!F12 -> 8 | H20: =Assumptions!H12-Assumptions!G12 -> 18
B21: Total net new sites | C21: sites | D21: =SUM(D16:D20) -> 5 | E21: =SUM(E16:E20) -> 15 | F21: =SUM(F16:F20) -> 42 | G21: =SUM(G16:G20) -> 78 | H21: =SUM(H16:H20) -> 116
B23: Setup / hardware revenue
B24: Clinics | C24: AED | D24: =D16*Assumptions!D15 -> 72000 | E24: =E16*Assumptions!E15 -> 190000 | F24: =F16*Assumptions!F15 -> 360000 | G24: =G16*Assumptions!G15 -> 588000 | H24: =H16*Assumptions!H15 -> 770000
B25: Hospitals | C25: AED | D25: =D17*Assumptions!D16 -> 45000 | E25: =E17*Assumptions!E16 -> 141000 | F25: =F17*Assumptions!F16 -> 400000 | G25: =G17*Assumptions!G16 -> 624000 | H25: =H17*Assumptions!H16 -> 770000
B26: Home-health | C26: AED | D26: =D18*Assumptions!D17 -> 0 | E26: =E18*Assumptions!E17 -> 26000 | F26: =F18*Assumptions!F17 -> 81000 | G26: =G18*Assumptions!G17 -> 140000 | H26: =H18*Assumptions!H17 -> 174000
B27: KSA + Other GCC | C27: AED | D27: =(D19+D20)*Assumptions!D18 -> 0 | E27: =(E19+E20)*Assumptions!E18 -> 0 | F27: =(F19+F20)*Assumptions!F18 -> 220000 | G27: =(G19+G20)*Assumptions!G18 -> 644000 | H27: =(H19+H20)*Assumptions!H18 -> 1320000
B28: Total setup revenue | C28: AED | D28: =SUM(D24:D27) -> 117000 | E28: =SUM(E24:E27) -> 357000 | F28: =SUM(F24:F27) -> 1061000 | G28: =SUM(G24:G27) -> 1996000 | H28: =SUM(H24:H27) -> 3034000
B30: Recurring SaaS revenue
B31: Clinics SaaS | C31: AED | D31: =12*Assumptions!D8*Assumptions!D34*Assumptions!D21 -> 108000 | E31: =12*(Assumptions!D8+(Assumptions!E8-Assumptions!D8)*Assumptions!E34)*Assumptions!E21 -> 507600 | F31: =12*(Assumptions!E8+(Assumptions!F8-Assumptions!E8)*Assumptions!F34)*Assumptions!F21 -> 1458240 | G31: =12*(Assumptions!F8+(Assumptions!G8-Assumptions!F8)*Assumptions!G34)*Assumptions!G21 -> 2986560 | H31: =12*(Assumptions!G8+(Assumptions!H8-Assumptions!G8)*Assumptions!H34)*Assumptions!H21 -> 5262900
B32: Hospitals SaaS | C32: AED | D32: =12*Assumptions!D9*Assumptions!D34*Assumptions!D22 -> 57000 | E32: =12*(Assumptions!D9+(Assumptions!E9-Assumptions!D9)*Assumptions!E34)*Assumptions!E22 -> 294000 | F32: =12*(Assumptions!E9+(Assumptions!F9-Assumptions!E9)*Assumptions!F34)*Assumptions!F22 -> 1056000 | G32: =12*(Assumptions!F9+(Assumptions!G9-Assumptions!F9)*Assumptions!G34)*Assumptions!G22 -> 2373120 | H32: =12*(Assumptions!G9+(Assumptions!H9-Assumptions!G9)*Assumptions!H34)*Assumptions!H22 -> 4210320
B33: Home-health SaaS | C33: AED | D33: =12*Assumptions!D10*Assumptions!D34*Assumptions!D23 -> 0 | E33: =12*(Assumptions!D10+(Assumptions!E10-Assumptions!D10)*Assumptions!E34)*Assumptions!E23 -> 37200 | F33: =12*(Assumptions!E10+(Assumptions!F10-Assumptions!E10)*Assumptions!F34)*Assumptions!F23 -> 215040 | G33: =12*(Assumptions!F10+(Assumptions!G10-Assumptions!F10)*Assumptions!G34)*Assumptions!G23 -> 554400 | H33: =12*(Assumptions!G10+(Assumptions!H10-Assumptions!G10)*Assumptions!H34)*Assumptions!H23 -> 1052640
B34: KSA + GCC SaaS | C34: AED | D34: =12*(Assumptions!D11*Assumptions!D34+Assumptions!D12*Assumptions!D34)*Assumptions!D24 -> 0 | E34: =12*((Assumptions!D11+(Assumptions!E11-Assumptions!D11)*Assumptions!E34)+(Assumptions!D12+(Assumptions!E12-Assumptions!D12)*Assumptions!E34))*Assumptions!E24 -> 0 | F34: =12*((Assumptions!E11+(Assumptions!F11-Assumptions!E11)*Assumptions!F34)+(Assumptions!E12+(Assumptions!F12-Assumptions!E12)*Assumptions!F34))*Assumptions!F24 -> 360000 | G34: =12*((Assumptions!F11+(Assumptions!G11-Assumptions!F11)*Assumptions!G34)+(Assumptions!F12+(Assumptions!G12-Assumptions!F12)*Assumptions!G34))*Assumptions!G24 -> 1672320 | H34: =12*((Assumptions!G11+(Assumptions!H11-Assumptions!G11)*Assumptions!H34)+(Assumptions!G12+(Assumptions!H12-Assumptions!G12)*Assumptions!H34))*Assumptions!H24 -> 4779000
B35: Total SaaS revenue | C35: AED | D35: =SUM(D31:D34) -> 165000 | E35: =SUM(E31:E34) -> 838800 | F35: =SUM(F31:F34) -> 3089280 | G35: =SUM(G31:G34) -> 7586400 | H35: =SUM(H31:H34) -> 15304860
B37: Per-session revenue
B38: Clinic sessions | C38: AED | D38: =12*Assumptions!D8*Assumptions!D34*Assumptions!D27*Assumptions!D31 -> 151200 | E38: =12*(Assumptions!D8+(Assumptions!E8-Assumptions!D8)*Assumptions!E34)*Assumptions!E27*Assumptions!E31 -> 902880 | F38: =12*(Assumptions!E8+(Assumptions!F8-Assumptions!E8)*Assumptions!F34)*Assumptions!F27*Assumptions!F31 -> 3249792 | G38: =12*(Assumptions!F8+(Assumptions!G8-Assumptions!F8)*Assumptions!G34)*Assumptions!G27*Assumptions!G31 -> 8151552 | H38: =12*(Assumptions!G8+(Assumptions!H8-Assumptions!G8)*Assumptions!H34)*Assumptions!H27*Assumptions!H31 -> 17476800
B39: Hospital sessions | C39: AED | D39: =12*Assumptions!D9*Assumptions!D34*Assumptions!D28*Assumptions!D31 -> 67200 | E39: =12*(Assumptions!D9+(Assumptions!E9-Assumptions!D9)*Assumptions!E34)*Assumptions!E28*Assumptions!E31 -> 433200 | F39: =12*(Assumptions!E9+(Assumptions!F9-Assumptions!E9)*Assumptions!F34)*Assumptions!F28*Assumptions!F31 -> 1951488 | G39: =12*(Assumptions!F9+(Assumptions!G9-Assumptions!F9)*Assumptions!G34)*Assumptions!G28*Assumptions!G31 -> 5529600 | H39: =12*(Assumptions!G9+(Assumptions!H9-Assumptions!G9)*Assumptions!H34)*Assumptions!H28*Assumptions!H31 -> 12233760
B40: Home-health sessions | C40: AED | D40: =12*Assumptions!D10*Assumptions!D34*Assumptions!D29*Assumptions!D31 -> 0 | E40: =12*(Assumptions!D10+(Assumptions!E10-Assumptions!D10)*Assumptions!E34)*Assumptions!E29*Assumptions!E31 -> 54720 | F40: =12*(Assumptions!E10+(Assumptions!F10-Assumptions!E10)*Assumptions!F34)*Assumptions!F29*Assumptions!F31 -> 508032 | G40: =12*(Assumptions!F10+(Assumptions!G10-Assumptions!F10)*Assumptions!G34)*Assumptions!G29*Assumptions!G31 -> 1774080 | H40: =12*(Assumptions!G10+(Assumptions!H10-Assumptions!G10)*Assumptions!H34)*Assumptions!H29*Assumptions!H31 -> 4427280
B41: KSA + GCC sessions | C41: AED | D41: =12*(Assumptions!D11*Assumptions!D34+Assumptions!D12*Assumptions!D34)*Assumptions!D30*Assumptions!D31 -> 0 | E41: =12*((Assumptions!D11+(Assumptions!E11-Assumptions!D11)*Assumptions!E34)+(Assumptions!D12+(Assumptions!E12-Assumptions!D12)*Assumptions!E34))*Assumptions!E30*Assumptions!E31 -> 0 | F41: =12*((Assumptions!E11+(Assumptions!F11-Assumptions!E11)*Assumptions!F34)+(Assumptions!E12+(Assumptions!F12-Assumptions!E12)*Assumptions!F34))*Assumptions!F30*Assumptions!F31 -> 604800 | G41: =12*((Assumptions!F11+(Assumptions!G11-Assumptions!F11)*Assumptions!G34)+(Assumptions!F12+(Assumptions!G12-Assumptions!F12)*Assumptions!G34))*Assumptions!G30*Assumptions!G31 -> 4013568 | H41: =12*((Assumptions!G11+(Assumptions!H11-Assumptions!G11)*Assumptions!H34)+(Assumptions!G12+(Assumptions!H12-Assumptions!G12)*Assumptions!H34))*Assumptions!H30*Assumptions!H31 -> 15576000
B42: Total session revenue | C42: AED | D42: =SUM(D38:D41) -> 218400 | E42: =SUM(E38:E41) -> 1390800 | F42: =SUM(F38:F41) -> 6314112 | G42: =SUM(G38:G41) -> 19468800 | H42: =SUM(H38:H41) -> 49713840
B44: TOTAL REVENUE (AED) | C44: AED | D44: =D28+D35+D42 -> 500400 | E44: =E28+E35+E42 -> 2586600 | F44: =F28+F35+F42 -> 10464392 | G44: =G28+G35+G42 -> 29051200 | H44: =H28+H35+H42 -> 68052700
B45: YoY growth | C45: % | E45: =E44/D44-1 -> 4.1690647 | F45: =F44/E44-1 -> 3.0456166 | G45: =G44/F44-1 -> 1.7761957 | H45: =H44/G44-1 -> 1.3425091
B46: TOTAL REVENUE (USD ref) | C46: USD | D46: =D44/Assumptions!D61 -> 136348.77 | E46: =E44/Assumptions!E61 -> 704795.64 | F46: =F44/Assumptions!F61 -> 2851333 | G46: =G44/Assumptions!G61 -> 7915858.3 | H46: =H44/Assumptions!H61 -> 18542970

Sheet COGS
B2: Cost of Goods Sold
B3: Hardware, hosting, content, support
B5: Line Item | C5: Unit | D5: FY2026 | E5: FY2027 | F5: FY2028 | G5: FY2029 | H5: FY2030
B7: Hardware (new sites) | C7: AED | D7: =(Revenue!D16+Revenue!D17*2.5+Revenue!D18*0.7+Revenue!D19+Revenue!D20)*Assumptions!D37 -> 58500 | E7: =(Revenue!E16+Revenue!E17*2.5+Revenue!E18*0.7+Revenue!E19+Revenue!E20)*Assumptions!E37 -> 160650 | F7: =(Revenue!F16+Revenue!F17*2.5+Revenue!F18*0.7+Revenue!F19+Revenue!F20)*Assumptions!F37 -> 417600 | G7: =(Revenue!G16+Revenue!G17*2.5+Revenue!G18*0.7+Revenue!G19+Revenue!G20)*Assumptions!G37 -> 725400 | H7: =(Revenue!H16+Revenue!H17*2.5+Revenue!H18*0.7+Revenue!H19+Revenue!H20)*Assumptions!H37 -> 1000500
B8: Cloud + hosting | C8: AED | D8: =12*Revenue!D13*Assumptions!D38 -> 10800 | E8: =12*Revenue!E13*Assumptions!E38 -> 40800 | F8: =12*Revenue!F13*Assumptions!F38 -> 119040 | G8: =12*Revenue!G13*Assumptions!G38 -> 252000 | H8: =12*Revenue!H13*Assumptions!H38 -> 430080
B9: Content licensing | C9: AED | D9: =(Revenue!D38+Revenue!D39+Revenue!D40+Revenue!D41)/Assumptions!D31*Assumptions!D39 -> 18720 | E9: =(Revenue!E38+Revenue!E39+Revenue!E40+Revenue!E41)/Assumptions!E31*Assumptions!E39 -> 109800 | F9: =(Revenue!F38+Revenue!F39+Revenue!F40+Revenue!F41)/Assumptions!F31*Assumptions!F39 -> 375840 | G9: =(Revenue!G38+Revenue!G39+Revenue!G40+Revenue!G41)/Assumptions!G31*Assumptions!G39 -> 811200 | H9: =(Revenue!H38+Revenue!H39+Revenue!H40+Revenue!H41)/Assumptions!H31*Assumptions!H39 -> 1807776
B10: Customer support (variable) | C10: AED | D10: =12*Revenue!D13*Assumptions!D40 -> 13200 | E10: =12*Revenue!E13*Assumptions!E40 -> 48000 | F10: =12*Revenue!F13*Assumptions!F40 -> 133920 | G10: =12*Revenue!G13*Assumptions!G40 -> 285600 | H10: =12*Revenue!H13*Assumptions!H40 -> 491520
B11: TOTAL COGS | C11: AED | D11: =SUM(D7:D10) -> 101220 | E11: =SUM(E7:E10) -> 359250 | F11: =SUM(F7:F10) -> 1046400 | G11: =SUM(G7:G10) -> 2074200 | H11: =SUM(H7:H10) -> 3729876
B13: Gross profit | C13: AED | D13: =Revenue!D44-D11 -> 399180 | E13: =Revenue!E44-E11 -> 2227350 | F13: =Revenue!F44-F11 -> 9417992 | G13: =Revenue!G44-G11 -> 26977000 | H13: =Revenue!H44-H11 -> 64322824
B14: Gross margin % | C14: % | D14: =IFERROR(D13/Revenue!D44,0) -> 0.79772182 | E14: =IFERROR(E13/Revenue!E44,0) -> 0.86111111 | F14: =IFERROR(F13/Revenue!F44,0) -> 0.90000375 | G14: =IFERROR(G13/Revenue!G44,0) -> 0.92860192 | H14: =IFERROR(H13/Revenue!H44,0) -> 0.94519136

Sheet OpEx
B2: Operating Expenses
B3: Headcount + non-payroll
B5: Line Item | C5: Unit | D5: FY2026 | E5: FY2027 | F5: FY2028 | G5: FY2029 | H5: FY2030
B7: Headcount (year-end FTEs)
B8: Engineering + Product | C8: FTE | D8: =Assumptions!D43 -> 4 | E8: =Assumptions!E43 -> 8 | F8: =Assumptions!F43 -> 14 | G8: =Assumptions!G43 -> 22 | H8: =Assumptions!H43 -> 32
B9: Clinical + Reg | C9: FTE | D9: =Assumptions!D44 -> 2 | E9: =Assumptions!E44 -> 4 | F9: =Assumptions!F44 -> 6 | G9: =Assumptions!G44 -> 9 | H9: =Assumptions!H44 -> 13
B10: Sales + CS | C10: FTE | D10: =Assumptions!D45 -> 2 | E10: =Assumptions!E45 -> 5 | F10: =Assumptions!F45 -> 12 | G10: =Assumptions!G45 -> 22 | H10: =Assumptions!H45 -> 38
B11: G&A | C11: FTE | D11: =Assumptions!D46 -> 1 | E11: =Assumptions!E46 -> 3 | F11: =Assumptions!F46 -> 5 | G11: =Assumptions!G46 -> 8 | H11: =Assumptions!H46 -> 12
B12: Total FTEs | C12: FTE | D12: =SUM(D8:D11) -> 9 | E12: =SUM(E8:E11) -> 20 | F12: =SUM(F8:F11) -> 37 | G12: =SUM(G8:G11) -> 61 | H12: =SUM(H8:H11) -> 95
B14: Avg FTEs during year
B15: Payroll cost
B16: Engineering + Product | C16: AED | D16: =D8/2*Assumptions!D47 -> 640000 | E16: =(E8+D8)/2*Assumptions!E47 -> 2040000 | F16: =(F8+E8)/2*Assumptions!F47 -> 3960000 | G16: =(G8+F8)/2*Assumptions!G47 -> 6840000 | H16: =(H8+G8)/2*Assumptions!H47 -> 10800000
B17: Clinical + Reg | C17: AED | D17: =D9/2*Assumptions!D47 -> 320000 | E17: =(E9+D9)/2*Assumptions!E47 -> 1020000 | F17: =(F9+E9)/2*Assumptions!F47 -> 1800000 | G17: =(G9+F9)/2*Assumptions!G47 -> 2850000 | H17: =(H9+G9)/2*Assumptions!H47 -> 4400000
B18: Sales + CS | C18: AED | D18: =D10/2*Assumptions!D47 -> 320000 | E18: =(E10+D10)/2*Assumptions!E47 -> 1190000 | F18: =(F10+E10)/2*Assumptions!F47 -> 3060000 | G18: =(G10+F10)/2*Assumptions!G47 -> 6460000 | H18: =(H10+G10)/2*Assumptions!H47 -> 12000000
B19: G&A | C19: AED | D19: =D11/2*Assumptions!D47 -> 160000 | E19: =(E11+D11)/2*Assumptions!E47 -> 680000 | F19: =(F11+E11)/2*Assumptions!F47 -> 1440000 | G19: =(G11+F11)/2*Assumptions!G47 -> 2470000 | H19: =(H11+G11)/2*Assumptions!H47 -> 4000000
B20: Total payroll | C20: AED | D20: =SUM(D16:D19) -> 1440000 | E20: =SUM(E16:E19) -> 4930000 | F20: =SUM(F16:F19) -> 10260000 | G20: =SUM(G16:G19) -> 18620000 | H20: =SUM(H16:H19) -> 31200000
B22: Non-payroll OpEx
B23: Marketing & demand gen | C23: AED | D23: =Assumptions!D50 -> 400000 | E23: =Assumptions!E50 -> 1500000 | F23: =Assumptions!F50 -> 4500000 | G23: =Assumptions!G50 -> 9000000 | H23: =Assumptions!H50 -> 16000000
B24: Regulatory + legal + IP | C24: AED | D24: =Assumptions!D51 -> 350000 | E24: =Assumptions!E51 -> 450000 | F24: =Assumptions!F51 -> 350000 | G24: =Assumptions!G51 -> 400000 | H24: =Assumptions!H51 -> 450000
B25: Travel & entertainment | C25: AED | D25: =Assumptions!D52 -> 120000 | E25: =Assumptions!E52 -> 350000 | F25: =Assumptions!F52 -> 800000 | G25: =Assumptions!G52 -> 1500000 | H25: =Assumptions!H52 -> 2500000
B26: Office, IT, software | C26: AED | D26: =Assumptions!D53 -> 180000 | E26: =Assumptions!E53 -> 380000 | F26: =Assumptions!F53 -> 720000 | G26: =Assumptions!G53 -> 1300000 | H26: =Assumptions!H53 -> 2200000
B27: Professional services | C27: AED | D27: =Assumptions!D54 -> 150000 | E27: =Assumptions!E54 -> 250000 | F27: =Assumptions!F54 -> 350000 | G27: =Assumptions!G54 -> 450000 | H27: =Assumptions!H54 -> 600000
B28: Other / contingency | C28: AED | D28: =Assumptions!D55 -> 100000 | E28: =Assumptions!E55 -> 250000 | F28: =Assumptions!F55 -> 500000 | G28: =Assumptions!G55 -> 850000 | H28: =Assumptions!H55 -> 1400000
B29: Total non-payroll | C29: AED | D29: =SUM(D23:D28) -> 1300000 | E29: =SUM(E23:E28) -> 3180000 | F29: =SUM(F23:F28) -> 7220000 | G29: =SUM(G23:G28) -> 13500000 | H29: =SUM(H23:H28) -> 23150000
B31: TOTAL OPEX | C31: AED | D31: =D20+D29 -> 2740000 | E31: =E20+E29 -> 8110000 | F31: =F20+F29 -> 17480000 | G31: =G20+G29 -> 32120000 | H31: =H20+H29 -> 54350000

Sheet P&L
B2: Income Statement
B3: FY2026–FY2030, AED
C5: Unit | D5: FY2026 | E5: FY2027 | F5: FY2028 | G5: FY2029 | H5: FY2030
B7: Revenue | C7: AED | D7: =Revenue!D44 -> 500400 | E7: =Revenue!E44 -> 2586600 | F7: =Revenue!F44 -> 10464392 | G7: =Revenue!G44 -> 29051200 | H7: =Revenue!H44 -> 68052700
B8: YoY growth | C8: % | E8: =E7/D7-1 -> 4.1690647 | F8: =F7/E7-1 -> 3.0456166 | G8: =G7/F7-1 -> 1.7761957 | H8: =H7/G7-1 -> 1.3425091
B9: Cost of Goods Sold | C9: AED | D9: =-COGS!D11 -> -101220 | E9: =-COGS!E11 -> -359250 | F9: =-COGS!F11 -> -1046400 | G9: =-COGS!G11 -> -2074200 | H9: =-COGS!H11 -> -3729876
B10: Gross profit | C10: AED | D10: =D7+D9 -> 399180 | E10: =E7+E9 -> 2227350 | F10: =F7+F9 -> 9417992 | G10: =G7+G9 -> 26977000 | H10: =H7+H9 -> 64322824
B11: Gross margin | C11: % | D11: =IFERROR(D10/D7,0) -> 0.79772182 | E11: =IFERROR(E10/E7,0) -> 0.86111111 | F11: =IFERROR(F10/F7,0) -> 0.90000375 | G11: =IFERROR(G10/G7,0) -> 0.92860192 | H11: =IFERROR(H10/H7,0) -> 0.94519136
B13: Operating expenses | C13: AED | D13: =-OpEx!D31 -> -2740000 | E13: =-OpEx!E31 -> -8110000 | F13: =-OpEx!F31 -> -17480000 | G13: =-OpEx!G31 -> -32120000 | H13: =-OpEx!H31 -> -54350000
B15: EBITDA | C15: AED | D15: =D10+D13 -> -2340820 | E15: =E10+E13 -> -5882650 | F15: =F10+F13 -> -8062008 | G15: =G10+G13 -> -5143000 | H15: =H10+H13 -> 9972824
B16: EBITDA margin | C16: % | D16: =IFERROR(D15/D7,0) -> -4.6778977 | E16: =IFERROR(E15/E7,0) -> -2.274279 | F16: =IFERROR(F15/F7,0) -> -0.77042297 | G16: =IFERROR(G15/G7,0) -> -0.17703227 | H16: =IFERROR(H15/H7,0) -> 0.1465456
B18: D&A (5-yr SL on capex) | C18: AED | D18: =-Assumptions!D59*Revenue!D44*0.2 -> -3002.4 | E18: =-Assumptions!E59*Revenue!E44*0.2 -> -15519.6 | F18: =-Assumptions!F59*Revenue!F44*0.2 -> -83715.136 | G18: =-Assumptions!G59*Revenue!G44*0.2 -> -232409.6 | H18: =-Assumptions!H59*Revenue!H44*0.2 -> -544421.6
B19: EBIT | C19: AED | D19: =D15+D18 -> -2343822.4 | E19: =E15+E18 -> -5898169.6 | F19: =F15+F18 -> -8145723.1 | G19: =G15+G18 -> -5375409.6 | H19: =H15+H18 -> 9428402.4
B21: Taxable EBIT (simple) | C21: AED | D21: =MAX(0,D19) -> 0 | E21: =MAX(0,E19) -> 0 | F21: =MAX(0,F19) -> 0 | G21: =MAX(0,G19) -> 0 | H21: =MAX(0,H19) -> 9428402.4
B22: Tax | C22: AED | D22: =-D21*Assumptions!D60 -> 0 | E22: =-E21*Assumptions!E60 -> 0 | F22: =-F21*Assumptions!F60 -> 0 | G22: =-G21*Assumptions!G60 -> 0 | H22: =-H21*Assumptions!H60 -> -848556.22
B23: Net Income | C23: AED | D23: =D19+D22 -> -2343822.4 | E23: =E19+E22 -> -5898169.6 | F23: =F19+F22 -> -8145723.1 | G23: =G19+G22 -> -5375409.6 | H23: =H19+H22 -> 8579846.2
B24: Net margin | C24: % | D24: =IFERROR(D23/D7,0) -> -4.6838977 | E24: =IFERROR(E23/E7,0) -> -2.280279 | F24: =IFERROR(F23/F7,0) -> -0.77842297 | G24: =IFERROR(G23/G7,0) -> -0.18503227 | H24: =IFERROR(H23/H7,0) -> 0.1260765

Sheet CashFlow
B2: Cash Flow
B3: Indirect method, AED
C5: Unit | D5: FY2026 | E5: FY2027 | F5: FY2028 | G5: FY2029 | H5: FY2030
B7: Net Income | C7: AED | D7: ='P&L'!D23 -> -2343822.4 | E7: ='P&L'!E23 -> -5898169.6 | F7: ='P&L'!F23 -> -8145723.1 | G7: ='P&L'!G23 -> -5375409.6 | H7: ='P&L'!H23 -> 8579846.2
B8: + D&A (add back non-cash) | C8: AED | D8: =-'P&L'!D18 -> 3002.4 | E8: =-'P&L'!E18 -> 15519.6 | F8: =-'P&L'!F18 -> 83715.136 | G8: =-'P&L'!G18 -> 232409.6 | H8: =-'P&L'!H18 -> 544421.6
B9: - Change in working capital | C9: AED | D9: =-Revenue!D44*Assumptions!D58 -> -50040 | E9: =-(Revenue!E44-Revenue!D44)*Assumptions!E58 -> -208620 | F9: =-(Revenue!F44-Revenue!E44)*Assumptions!F58 -> -945335.04 | G9: =-(Revenue!G44-Revenue!F44)*Assumptions!G58 -> -2230417 | H9: =-(Revenue!H44-Revenue!G44)*Assumptions!H58 -> -4680180
B10: Cash from operations | C10: AED | D10: =SUM(D7:D9) -> -2390860 | E10: =SUM(E7:E9) -> -6091270 | F10: =SUM(F7:F9) -> -9007343 | G10: =SUM(G7:G9) -> -7373417 | H10: =SUM(H7:H9) -> 4444087.8
B12: - Capex | C12: AED | D12: =-Revenue!D44*Assumptions!D59 -> -15012 | E12: =-Revenue!E44*Assumptions!E59 -> -77598 | F12: =-Revenue!F44*Assumptions!F59 -> -418575.68 | G12: =-Revenue!G44*Assumptions!G59 -> -1162048 | H12: =-Revenue!H44*Assumptions!H59 -> -2722108
B13: Cash from investing | C13: AED | D13: =D12 -> -15012 | E13: =E12 -> -77598 | F13: =F12 -> -418575.68 | G13: =G12 -> -1162048 | H13: =H12 -> -2722108
B15: Financing — equity raises | C15: AED | D15: 0 | E15: 0 | F15: 0 | G15: 0 | H15: 0
B16: Cash from financing | C16: AED | D16: =D15 -> 0 | E16: =E15 -> 0 | F16: =F15 -> 0 | G16: =G15 -> 0 | H16: =H15 -> 0
B18: Net change in cash | C18: AED | D18: =D10+D13+D16 -> -2405872 | E18: =E10+E13+E16 -> -6168868 | F18: =F10+F13+F16 -> -9425918.7 | G18: =G10+G13+G16 -> -8535465 | H18: =H10+H13+H16 -> 1721979.8
B19: Cumulative cash position (pre-funding) | C19: AED | D19: =D18 -> -2405872 | E19: =D19+E18 -> -8574740 | F19: =E19+F18 -> -18000659 | G19: =F19+G18 -> -26536124 | H19: =G19+H18 -> -24814144

Sheet Funding
B2: Capital Plan
B3: 4 funding rounds: pre-seed → seed → Series A → Series B
B5: Round | C5: Date | D5: Amount (AED M) | E5: Pre-money (AED M) | F5: Post-money (AED M) | G5: Dilution | H5: Use of Funds
B6: Pre-Seed | C6: Q3 2026 | D6: 0.4 | E6: 3.6 | F6: =E6+D6 -> 4 | G6: =D6/F6 -> 0.1 | H6: Founder + angels; runway to first paid pilots
B7: Seed | C7: Q4 2026 | D7: 5.5 | E7: 18 | F7: =E7+D7 -> 23.5 | G7: =D7/F7 -> 0.23404255 | H7: VC-led; UAE rollout, MoHAP filing, 8-person team
B8: Series A | C8: Q2 2028 | D8: 28 | E8: 95 | F8: =E8+D8 -> 123 | G8: =D8/F8 -> 0.22764228 | H8: Regional VC; KSA entry, full clinical evidence, 35-person team
B9: Series B | C9: Q4 2029 | D9: 80 | E9: 380 | F9: =E9+D9 -> 460 | G9: =D9/F9 -> 0.17391304 | H9: Growth round; broader GCC, prep for global expansion
B11: Total raised (AED M) | D11: =SUM(D6:D9) -> 113.9
B12: Total raised (USD M) | D12: =D11/Assumptions!D61 -> 31.035422

Sheet CapTable
B2: Cap Table — Ownership Evolution
B3: % ownership after each round
B5: Stakeholder | C5: Founding | D5: Post Pre-Seed | E5: Post Seed | F5: Post Series A | G5: Post Series B
B6: Founders | C6: 0.9 | D6: =C6*(1-Funding!G6) -> 0.81 | E6: =D6*(1-Funding!G7) -> 0.62042553 | F6: =E6*(1-Funding!G8) -> 0.47919045 | G6: =F6*(1-Funding!G9) -> 0.39585298
B7: ESOP | C7: 0.1 | D7: =C7*(1-Funding!G6) -> 0.09 | E7: =D7*(1-Funding!G7)+0.05*Funding!G7 -> 0.080638298 | F7: =E7*(1-Funding!G8)+0.03*Funding!G8 -> 0.06911088 | G7: =F7*(1-Funding!G9)+0.02*Funding!G9 -> 0.060569858
B8: Pre-Seed angels | C8: 0 | D8: =Funding!G6 -> 0.1 | E8: =D8*(1-Funding!G7) -> 0.076595745 | F8: =E8*(1-Funding!G8) -> 0.059159315 | G8: =F8*(1-Funding!G9) -> 0.048870738
B9: Seed investors | C9: 0 | D9: 0 | E9: =Funding!G7*0.95 -> 0.22234043 | F9: =E9*(1-Funding!G8) -> 0.17172634 | G9: =F9*(1-Funding!G9) -> 0.14186089
B10: Series A investors | C10: 0 | D10: 0 | E10: 0 | F10: =Funding!G8*0.97 -> 0.22081301 | G10: =F10*(1-Funding!G9) -> 0.18241075
B11: Series B investors | C11: 0 | D11: 0 | E11: 0 | F11: 0 | G11: =Funding!G9*0.98 -> 0.17043478
B12: TOTAL | C12: =SUM(C6:C11) -> 1 | D12: =SUM(D6:D11) -> 1 | E12: =SUM(E6:E11) -> 1 | F12: =SUM(F6:F11) -> 1 | G12: =SUM(G6:G11) -> 1

Sheet Scenarios
B2: Scenarios — Sensitivity
B3: Conservative (-30% sites, -15% ARPU) / Base / Aggressive (+30% sites, +10% ARPU)
B5: Metric | C5: Scenario | D5: FY2026 | E5: FY2027 | F5: FY2028 | G5: FY2029 | H5: FY2030
B6: Revenue | C6: Base | D6: =Revenue!D44 -> 500400 | E6: =Revenue!E44 -> 2586600 | F6: =Revenue!F44 -> 10464392 | G6: =Revenue!G44 -> 29051200 | H6: =Revenue!H44 -> 68052700
B7: Revenue | C7: Conservative (-40%) | D7: =Revenue!D44*0.6 -> 300240 | E7: =Revenue!E44*0.6 -> 1551960 | F7: =Revenue!F44*0.6 -> 6278635.2 | G7: =Revenue!G44*0.6 -> 17430720 | H7: =Revenue!H44*0.6 -> 40831620
B8: Revenue | C8: Aggressive (+35%) | D8: =Revenue!D44*1.35 -> 675540 | E8: =Revenue!E44*1.35 -> 3491910 | F8: =Revenue!F44*1.35 -> 14126929 | G8: =Revenue!G44*1.35 -> 39219120 | H8: =Revenue!H44*1.35 -> 91871145
B9: EBITDA | C9: Base | D9: ='P&L'!D15 -> -2340820 | E9: ='P&L'!E15 -> -5882650 | F9: ='P&L'!F15 -> -8062008 | G9: ='P&L'!G15 -> -5143000 | H9: ='P&L'!H15 -> 9972824
B10: EBITDA | C10: Conservative | D10: ='P&L'!D15-Revenue!D44*0.4*0.55 -> -2450908 | E10: ='P&L'!E15-Revenue!E44*0.4*0.55 -> -6451702 | F10: ='P&L'!F15-Revenue!F44*0.4*0.55 -> -10364174 | G10: ='P&L'!G15-Revenue!G44*0.4*0.55 -> -11534264 | H10: ='P&L'!H15-Revenue!H44*0.4*0.55 -> -4998770
B11: EBITDA | C11: Aggressive | D11: ='P&L'!D15+Revenue!D44*0.35*0.6 -> -2235736 | E11: ='P&L'!E15+Revenue!E44*0.35*0.6 -> -5339464 | F11: ='P&L'!F15+Revenue!F44*0.35*0.6 -> -5864485.7 | G11: ='P&L'!G15+Revenue!G44*0.35*0.6 -> 957752 | H11: ='P&L'!H15+Revenue!H44*0.35*0.6 -> 24263891

Sheet Summary
B2: Executive Summary
B3: Five-year base case at a glance
C5: Unit | D5: FY2026 | E5: FY2027 | F5: FY2028 | G5: FY2029 | H5: FY2030
B6: Total sites (year-end) | C6: # | D6: =Revenue!D13 -> 5 | E6: =Revenue!E13 -> 20 | F6: =Revenue!F13 -> 62 | G6: =Revenue!G13 -> 140 | H6: =Revenue!H13 -> 256
B7: Revenue | C7: AED | D7: =Revenue!D44 -> 500400 | E7: =Revenue!E44 -> 2586600 | F7: =Revenue!F44 -> 10464392 | G7: =Revenue!G44 -> 29051200 | H7: =Revenue!H44 -> 68052700
B8: YoY growth | C8: % | E8: =Revenue!E44/Revenue!D44-1 -> 4.1690647 | F8: =Revenue!F44/Revenue!E44-1 -> 3.0456166 | G8: =Revenue!G44/Revenue!F44-1 -> 1.7761957 | H8: =Revenue!H44/Revenue!G44-1 -> 1.3425091
B9: Gross profit | C9: AED | D9: ='P&L'!D10 -> 399180 | E9: ='P&L'!E10 -> 2227350 | F9: ='P&L'!F10 -> 9417992 | G9: ='P&L'!G10 -> 26977000 | H9: ='P&L'!H10 -> 64322824
B10: Gross margin | C10: % | D10: ='P&L'!D11 -> 0.79772182 | E10: ='P&L'!E11 -> 0.86111111 | F10: ='P&L'!F11 -> 0.90000375 | G10: ='P&L'!G11 -> 0.92860192 | H10: ='P&L'!H11 -> 0.94519136
B11: OpEx | C11: AED | D11: =OpEx!D31 -> 2740000 | E11: =OpEx!E31 -> 8110000 | F11: =OpEx!F31 -> 17480000 | G11: =OpEx!G31 -> 32120000 | H11: =OpEx!H31 -> 54350000
B12: EBITDA | C12: AED | D12: ='P&L'!D15 -> -2340820 | E12: ='P&L'!E15 -> -5882650 | F12: ='P&L'!F15 -> -8062008 | G12: ='P&L'!G15 -> -5143000 | H12: ='P&L'!H15 -> 9972824
B13: EBITDA margin | C13: % | D13: ='P&L'!D16 -> -4.6778977 | E13: ='P&L'!E16 -> -2.274279 | F13: ='P&L'!F16 -> -0.77042297 | G13: ='P&L'!G16 -> -0.17703227 | H13: ='P&L'!H16 -> 0.1465456
B14: Net Income | C14: AED | D14: ='P&L'!D23 -> -2343822.4 | E14: ='P&L'!E23 -> -5898169.6 | F14: ='P&L'!F23 -> -8145723.1 | G14: ='P&L'!G23 -> -5375409.6 | H14: ='P&L'!H23 -> 8579846.2
B16: Revenue (USD M) | C16: USD M | D16: =Revenue!D44/Assumptions!D61/1000000 -> 0.13634877 | E16: =Revenue!E44/Assumptions!E61/1000000 -> 0.70479564 | F16: =Revenue!F44/Assumptions!F61/1000000 -> 2.851333 | G16: =Revenue!G44/Assumptions!G61/1000000 -> 7.9158583 | H16: =Revenue!H44/Assumptions!H61/1000000 -> 18.54297
B17: EBITDA (USD M) | C17: USD M | D17: ='P&L'!D15/Assumptions!D61/1000000 -> -0.63782561 | E17: ='P&L'!E15/Assumptions!E61/1000000 -> -1.6029019 | F17: ='P&L'!F15/Assumptions!F61/1000000 -> -2.1967324 | G17: ='P&L'!G15/Assumptions!G61/1000000 -> -1.4013624 | H17: ='P&L'!H15/Assumptions!H61/1000000 -> 2.7173907
